<?xml version="1.0" ?>
<robot name="podcar_2">
  <link name="base_link">
    <visual name="prettyMesh">
        <origin xyz ="0 0 0" rpy="0 0 1.57079"/>
        <geometry>
          <mesh filename="package://orange_description/meshes/podcarv3.dae" />
            <!-- <scale>65 69 69</scale> -->
        </geometry>
        <material>
          <ambient> 0 0 0.8 0
          </ambient>
          <emissive> 0.0 0 0 0
          </emissive>
        </material>
     </visual>
    <collision name="collision">
        <origin xyz="0 0 0.25" rpy=" 0 0 0"/>
        <geometry>
          <box size="1.6 0.73 0.1"/>
        </geometry>
     </collision>      
     <inertial>
        <mass value="33.855"/>
        <origin rpy="-0.0856132 -0.000839955 0.238145" xyz=" 0 0 0"/>
        <inertia>
          <ixx>2.2343</ixx>
          <ixy>-0.023642</ixy>
          <ixz>0.275174</ixz>
          <iyy>3.42518</iyy>
          <iyz>0.00239624</iyz>
          <izz>2.1241</izz>
        </inertia>
      </inertial>
   </link>
   <!-- should we add base_inertia and base_inertia_joint -->
   <!--######### Adding the joints and links of wheels -->
   
   <link name="back_left_wheel">
      <origin xyz="-0.6  0.285475 0.0" rpy="0 0 0"/>
      <inertial>
        <mass value="2.6357"/>
        <origin xyz="0 0 0" rpy="0 0 0"/>
        <inertia>
          <ixx>0.0246688</ixx>
          <ixy>0</ixy>
          <ixz>0</ixz>
          <iyy>0.0246688</iyy>
          <iyz>0</iyz>
          <izz>0.0441058</izz>
        </inertia>
      </inertial>
      <collision name="back_left_wheel_collision">
        <origin xyz="0 0 0" rpy= "-1.5707 0 0"/>
        <geometry>
          <cylinder length="0.1143" radius="0.17775"/>
            
        </geometry>
        
        <!--<surface>
          <friction>
            <ode>
              <mu>10</mu>
              <mu2>1</mu2>
              <slip1>0.0</slip1>
              <slip2>0.0</slip2>
            </ode>
          </friction>
        </surface> -->
        
      </collision>
      <visual name="back_left_wheel">
        <origin xyz="0 0 0" rpy="-3.14159 0 0"/>
        <geometry>
          <mesh filename="package://ubr1_description/meshes/right_wheel_link.STL" />
            
        </geometry>
        <material>
          <script>
            <name>Gazebo/Grey</name>
          </script>
        </material>
       </visual>
      </link>
      <joint name="back_left_joint" type="revolute">
      <parent link="base_link"/>
      <child link="back_left_wheel"/>
      <axis xyz="0 1 0"/>
      
        <use_parent_model_frame>true</use_parent_model_frame>
      <!-- look at the physiccs part in URDF -->
      <physics>
        <ode>
          <limit>
            <cfm>0.000000</cfm>
            <erp>0.900000</erp>
          </limit>
        </ode>
      </physics>
    </joint>
    
    <!-- ###### Adding other link #######-->
    
    <link name="back_right_wheel">
      <!--<pose>-0.6 -0.285475 0.0  0 0 0</pose> -->
      
      <inertial>
        <mass value="2.6357"/>
        <origin xyz="0 0 0" rpy="0 0 0"/>
        <inertia>
          <ixx>0.0246688</ixx>
          <ixy>0</ixy>
          <ixz>0</ixz>
          <iyy>0.0246688</iyy>
          <iyz>0</iyz>
          <izz>0.0441058</izz>
        </inertia>
      </inertial>
      <collision name="back_right_wheel_collision">
        <origin xyz="0 0 0" rpy="-1.5707 0 0"/>
        <geometry>
          <cylinder length="0.1143" radius="0.17775"/>
            
          
        </geometry>
        
        <!-- <surface>
          <friction>
            <ode>
              <mu>10</mu>
              <mu2>1</mu2>
              <slip1>0.0</slip1>
              <slip2>0.0</slip2>
            </ode>
          </friction>
        </surface> -->
        
      </collision>
      <visual name="back_right_wheel">
        <origin xyz="0 0 0" rpy="-3.14159 0 0"/>
        <geometry>
          <mesh filename="package://orange_description/meshes/wheel.stl"/>
            
        </geometry>
        <material name=" ">
         <color rgba="0.909803921568627 0.443137254901961 0.0313725490196078 1"/>
          <!--<script>
            <name>Gazebo/Grey</name>
          </script> -->
        </material>
      </visual>
    </link>
    <joint name="back_right_joint" type="revolute">
      <parent link="base_link" />
      <child link="back_right_wheel" />
      <axis>
        <xyz>0 1 0</xyz>
        <use_parent_model_frame>true</use_parent_model_frame>
        <dynamics>
          <friction>0.5</friction>
        </dynamics>
      </axis>
      <!--<physics>
        <ode>
          <limit>
            <cfm>0.000000</cfm>
            <erp>0.900000</erp>
          </limit>
        </ode>
      </physics> -->
    </joint>
    
    
    <!--testing-->
    
    <link name="front_left_pivot">
      <origin xyz="0.6 0.285475 0.0" rpy=" 0 0 0"/>
      <inertial>
        <mass value="2.6357"/>
        <origin xyz="0 0 0" rpy="0 0 0"/>
        <inertia>
          <ixx>0.0246688</ixx>
          <ixy>0</ixy>
          <ixz>0</ixz>
          <iyy>0.0246688</iyy>
          <iyz>0</iyz>
          <izz>0.0441058</izz>
        </inertia>
      </inertial>
    </link>
    <joint name="front_left_pivot_joint" type="revolute">
      <parent link="base_link"/>
      <child link="front_left_pivot"/>
      <axis>
        <xyz>0 0 1</xyz>
        <use_parent_model_frame>true</use_parent_model_frame>
      </axis>
      <!--<physics>
        <ode>
          <limit>
            <cfm>0.000000</cfm>
            <erp>0.900000</erp>
          </limit>
        </ode>
      </physics> -->
    </joint>
    
    <!--###########Adding other link and joint-->
    
    <link name="front_left_wheel">
      <origij xyz="0.6 0.285475 0.0" rpy="0 0 0"</pose>
      <inertial>
        <mass value="2.6357"/>
        <origin xyz="0 0 0" rpy="0 0 0"/>
        <inertia>
          <ixx>0.0246688</ixx>
          <ixy>0</ixy>
          <ixz>0</ixz>
          <iyy>0.0246688</iyy>
          <iyz>0</iyz>
          <izz>0.0441058</izz>
        </inertia>
      </inertial>
      <collision name="front_left_wheel_collision">
        <origin xyz="0 0 0" rpy="-1.5707 0 0"/>
        <geometry>
          <cylinder length="0.11432" radius="0.17775"/>
            
        </geometry>
        
        <!--<surface>
          <friction>
            <ode>
              <mu>0.5</mu>
              <mu2>10</mu2>
              <slip1>0.01</slip1>
              <slip2>0.001</slip2>
            </ode>
          </friction>
        </surface> -->
        
      </collision>
      <visual name="front_left_wheel">
        <origin xyz="0 0 0" rpy=" -3.14159 0 0"/>
        <geometry>
          <mesh filename="package://ubr1_description/meshes/wheel.stl" />
            
        </geometry>
        
        <!--<material>
          <script>
            <name>Gazebo/Grey</name>
          </script>
        </material>-->
        
      </visual>
    </link>
    <joint name="front_left_joint" type="revolute">
      <parent link="front_left_pivot"/>
      <child link="front_left_wheel"/>
      <axis>
        <xyz>0 1 0</xyz>
        <use_parent_model_frame>false</use_parent_model_frame>
      </axis>
      
      <!--<physics>
        <ode>
          <limit>
            <cfm>0.000000</cfm>
            <erp>0.900000</erp>
          </limit>
        </ode>
      </physics>-->
      
    </joint>
    
    <!--testing-->
    
    <link name="front_right_pivot">
      <origin xyz="0.6 -0.285475 0.0" rpy=" 0 0 0"/>
      <inertial>
        <mass value="2.6357"/>
        <origin xyz="0 0 0" rpy="0 0 0"/>
        <inertia>
          <ixx>0.0246688</ixx>
          <ixy>0</ixy>
          <ixz>0</ixz>
          <iyy>0.0246688</iyy>
          <iyz>0</iyz>
          <izz>0.0441058</izz>
        </inertia>
      </inertial>
    <joint name="front_right_pivot_joint" type="revolute">
      <parent link="base_link"/>
      <child link="front_right_pivot"/>
      <axis>
        <xyz>0 0 1</xyz>
        <use_parent_model_frame>true</use_parent_model_frame>
      </axis>
      
      <!--<physics>
        <ode>
          <limit>
            <cfm>0.000000</cfm>
            <erp>0.900000</erp>
          </limit>
        </ode>
      </physics>-->
      
    </joint>


<!--########### Adding front wheel with links and joints##########-->

    <link name="front_right_wheel">
      <origin xyz="0.6 -0.285475 0.0" rpy=" 0 0 0"/>
      <inertial>
        <mass value="2.6357"/>
        <origin xyz="0 0 0" rpy="0 0 0"/>
        <inertia>
          <ixx>0.0246688</ixx>
          <ixy>0</ixy>
          <ixz>0</ixz>
          <iyy>0.0246688</iyy>
          <iyz>0</iyz>
          <izz>0.0441058</izz>
        </inertia>
      </inertial>
      <collision name="front_left_wheel_collision">
        <origin xyz="0 0 0" rpy="-1.5707 0 0"/>
        <geometry>
          <cylinder length="0.11432" radius="0.17775"/>
            
        </geometry>
        
        <!--<surface>
          <friction>
            <ode>
              <mu>0.5</mu>
              <mu2>10</mu2>
              <slip1>0.01</slip1>
              <slip2>0.001</slip2>
            </ode>
          </friction>
        </surface> -->
        
      </collision>
      <visual name="front_right_wheel">
        <origin xyz="0 0 0" rpy=" -3.14159 0 0"/>
        <geometry>
          <mesh filename="package://ubr1_description/meshes/wheel.stl" />
            
        </geometry>
        
        <!--<material>
          <script>
            <name>Gazebo/Grey</name>
          </script>
        </material>-->
        
      </visual>
    </link>
    <joint name="front_right_joint" type="revolute">
      <parent link="front_right_pivot"/>
      <child link="front_right_pivot"/>
      <axis>
        <xyz>0 0 1</xyz>
        <use_parent_model_frame>true</use_parent_model_frame>
      </axis>
      
      <!--<physics>
        <ode>
          <limit>
            <cfm>0.000000</cfm>
            <erp>0.900000</erp>
          </limit>
        </ode>
      </physics>-->
    </joint>
    
    <!--##############Adding Trackingrod link and joint#######-->
    <link name="trackingrod">
      <origin xyz="0.5 0 0.0" rpy="0 0 0"/>
      <inertial>
        <mass value="2.6357"/>
        <origin xyz="0 0 0" rpy=" 0 0 0"/>
        <inertia>
          <ixx>0.0246688</ixx>
          <ixy>0</ixy>
          <ixz>0</ixz>
          <iyy>0.0246688</iyy>
          <iyz>0</iyz>
          <izz>0.0441058</izz>
        </inertia>
      </inertial>
      <visual name='trackingrod_visual'>
        <origin xyz="0.0 0 0" rpy=" 0 0 0"/>
        <geometry>
          <box size="0.1 0.7 0.1"/>
            
        </geometry>
        <material>
          <ambient> 1.0 0 0.0 0
          </ambient>
          <emissive> 0.0 0 0 0
          </emissive>
        </material>
      </visual>
    </link>
	  <!--###is joined at center of wheel basis origin, not at edge of wheel###-->
	  
    <joint name="tracking_right_pivot_joint" type="revolute">
      <parent link="trackingrod"/>
      <child link="front_right_pivot2"/>
	    <!--<pose>-.1 0 0 0 0 0 </pose>-->
	    <origin xyz="0.1 0 0" rpy="0 0 0"/>
      <axis>
        <dynamics>
          <friction>1</friction>
        </dynamics>
        <limit>
          <lower>-0.82393858467</lower>
          <upper>0.82393858467</upper>
        </limit>
        <xyz>0 0 1</xyz>
        <use_parent_model_frame>false</use_parent_model_frame>
      </axis>
      <!--<physics>
        <ode>
          <limit>
            <cfm>0.000000</cfm>
            <erp>0.900000</erp>
          </limit>
        </ode>
      </physics>-->
    </joint>
    
    <joint name="tracking_left_pivot_joint" type="revolute">
      <parent link="trackingrod"/>
      <child link="front_left_pivot"/>
	    <origin xyz="-.1 0 0" rpy="0 0 0"/>
      <axis>
        <dynamics>
          <friction>1</friction>
        </dynamics>
        <limit>
          <lower>-0.82393858467</lower>
          <upper>0.82393858467</upper>
        </limit>
        <xyz>0 0 1</xyz>
        <use_parent_model_frame>false</use_parent_model_frame>
      </axis>
      <!--<physics>
        <ode>
          <limit>
            <cfm>0.000000</cfm>
            <erp>0.900000</erp>
          </limit>
        </ode>
      </physics>-->
    </joint>
    



    
   
      
